Workbook

Sheet Output Produzione
B1: Caso 0
B2: Month | C2: Energy to Community [MWh] | D2: Energy to Market [MWh] | E2: Energy from Community [MWh] | F2: Syngas [MWh/y] | G2: Hydrogen [MWh/y]
B3: 1 | C3: 35367.718 | D3: 44297.227 | E3: 0 | F3: 417245.84 | G3: =174008.17 -> 174008.17
B4: 2 | C4: 29498.951 | D4: 40716.36 | E4: 0
B5: 3 | C5: 31329.61 | D5: 43233.683 | E5: 0
B6: 4 | C6: 28800.111 | D6: 37584.3 | E6: 0
B7: 5 | C7: 29505.568 | D7: 38958.224 | E7: 0
B8: 6 | C8: 28599.408 | D8: 37878.908 | E8: 0
B9: 7 | C9: 30096.535 | D9: 39440.053 | E9: 0
B10: 8 | C10: 29512.936 | D10: 39046.023 | E10: 0
B11: 9 | C11: 28491.88 | D11: 38142.304 | E11: 0
B12: 10 | C12: 30358.567 | D12: 41768.648 | E12: 0
B13: 11 | C13: 32304.268 | D13: 42802.843 | E13: 0
B14: 12 | C14: 35391.709 | D14: 43690.913 | E14: 0
B15: Caso 1
B16: Month | C16: Energy to Community [MWh] | D16: Energy to Market [MWh] | E16: Energy from Community [MWh] | F16: Syngas [MWh/y] | G16: Hydrogen [MWh/y]
B17: 1 | C17: 36163.881 | D17: 36084.308 | E17: 0 | F17: 418912.28 | G17: =4819970*36.11/1000 -> 174049.12
B18: 2 | C18: 28275.132 | D18: 33920.279 | E18: 0
B19: 3 | C19: 28566.78 | D19: 39631.364 | E19: 0
B20: 4 | C20: 24649.181 | D20: 41368.142 | E20: 0
B21: 5 | C21: 24900.42 | D21: 43326.333 | E21: 0
B22: 6 | C22: 23439.207 | D22: 42113.408 | E22: 0
B23: 7 | C23: 24795.541 | D23: 43440.846 | E23: 0
B24: 8 | C24: 24642.725 | D24: 42761.643 | E24: 0
B25: 9 | C25: 24578.284 | D25: 41769.868 | E25: 0
B26: 10 | C26: 27327.903 | D26: 41269.775 | E26: 0
B27: 11 | C27: 30921.629 | D27: 35944.191 | E27: 0
B28: 12 | C28: 35930.24 | D28: 35601.223 | E28: 0
B29: Caso 2
B30: Month | C30: Energy to Community [MWh] | D30: Energy to Market [MWh] | E30: Energy from Community [MWh] | F30: Syngas [MWh/y] | G30: Hydrogen [MWh/y]
B31: 1 | C31: 34990.909 | D31: 37138.307 | E31: 0 | F31: 424581.22 | G31: =174240.14 -> 174240.14
B32: 2 | C32: 25234.331 | D32: 36344.52 | E32: 9.8532983
B33: 3 | C33: 24578.924 | D33: 43841.879 | E33: 279.06456
B34: 4 | C34: 20294.71 | D34: 46412.964 | E34: 603.98304
B35: 5 | C35: 20713.849 | D35: 47545.14 | E35: 536.28285
B36: 6 | C36: 18507.844 | D36: 47220.855 | E36: 707.69193
B37: 7 | C37: 19678.924 | D37: 48840.485 | E37: 560.67999
B38: 8 | C38: 19998.281 | D38: 48156.453 | E38: 484.94321
B39: 9 | C39: 20914.644 | D39: 46194.806 | E39: 143.57074
B40: 10 | C40: 24369.361 | D40: 43110.246 | E40: 18.626697
...

Sheet Prezzi Energia Vari
B2: REVENUES ENERGY TO COMMUNITY
C4: AVG PUN ZONALE NORD [€/MWh]
C5: 2023 | D5: 2024 | E5: 2025 | F5: Media
B6: gen | C6: 176.94 | D6: 99.34 | E6: 143.32 | F6: =0.4*E6+0.35*D6+0.25*C6 -> 136.332
B7: feb | C7: 162.12 | D7: 87.91 | E7: 150.56 | F7: =0.4*E7+0.35*D7+0.25*C7 -> 131.5225
B8: mar | C8: 140.82 | D8: 89.32 | E8: 121.08 | F8: =0.4*E8+0.35*D8+0.25*C8 -> 114.899
B9: apr | C9: 135.55 | D9: 87.28 | E9: 100.27 | F9: =0.4*E9+0.35*D9+0.25*C9 -> 104.5435
B10: mag | C10: 105.53 | D10: 94.16 | E10: 93.79 | F10: =0.4*E10+0.35*D10+0.25*C10 -> 96.8545
B11: giu | C11: 105.35 | D11: 101.39 | E11: =E10*(1+(((C11-C10)/C10)+((D11-D10)/D10))/2) -> 97.310807 | F11: =0.4*E11+0.35*D11+0.25*C11 -> 100.74832
B12: lug | C12: 110.61 | D12: 107.61 | E12: =E11*(1+(((C12-C11)/C11)+((D12-D11)/D11))/2) -> 102.72499 | F12: =0.4*E12+0.35*D12+0.25*C12 -> 106.406
B13: ago | C13: 111.17 | D13: 124.47 | E13: =E12*(1+(((C13-C12)/C12)+((D13-D12)/D12))/2) -> 111.03235 | F13: =0.4*E13+0.35*D13+0.25*C13 -> 115.76994
B14: sett | C14: 116.15 | D14: 115.78 | E14: =E13*(1+(((C14-C13)/C13)+((D14-D13)/D13))/2) -> 109.64334 | F14: =0.4*E14+0.35*D14+0.25*C14 -> 113.41784
B15: ott | C15: 133.46 | D15: 114.41 | E15: =E14*(1+(((C15-C14)/C14)+((D15-D14)/D14))/2) -> 117.1648 | F15: =0.4*E15+0.35*D15+0.25*C15 -> 120.27442
B16: nov | C16: 122.01 | D16: 130.67 | E16: =E15*(1+(((C16-C15)/C15)+((D16-D15)/D15))/2) -> 120.46457 | F16: =0.4*E16+0.35*D16+0.25*C16 -> 124.42283
B17: dic | C17: 115.76 | D17: 135.34 | E17: =E16*(1+(((C17-C16)/C16)+((D17-D16)/D16))/2) -> 119.53179 | F17: =0.4*E17+0.35*D17+0.25*C17 -> 124.12172
B20: PREZZO ELETTRICITA MEDIO ANNUALE per RITIRO DEDICATO [€/MWh]
B21: 46.8
B23: PREZZO GAS MEDIO ANNUALE [€/MWh]
B24: 120
B26: PREZZO IDROGENO* [€/MWh]
B27: =240 -> 240
B29: PREZZO ELETTRICITA MEDIO ANNUALE per COMMUNITY [€/MWh]
B30: Caso 0 | D30: Caso 1 | F30: Caso 2 | H30: Caso 3
B31: =SUMPRODUCT(F6:F17,'Output Produzione'!C3:C14)/SUM('Output Produzione'!C3:C14)*90% -> 104.72089 | D31: =SUMPRODUCT(F6:F17,'Output Produzione'!C17:C28)/SUM('Output Produzione'!C17:C28)*90% -> 105.44537 | F31: =SUMPRODUCT(F6:F17,'Output Produzione'!C31:C42)/SUM('Output Produzione'!C31:C42)*90% -> 106.06665 | H31: =SUMPRODUCT(F6:F17,'Output Produzione'!C45:C56)/SUM('Output Produzione'!C45:C56)*90% -> 106.29154
B32: PREZZO ELETTRICITA MEDIO ANNUALE per MERCATO [€/MWh]
B33: Caso 0 | D33: Caso 1 | F33: Caso 2 | H33: Caso 3
B34: =SUMPRODUCT(F6:F17,'Output Produzione'!C3:C14)/SUM('Output Produzione'!C3:C14) -> 116.35655 | D34: =SUMPRODUCT(F6:F17,'Output Produzione'!C17:C28)/SUM('Output Produzione'!C17:C28) -> 117.16153 | F34: =SUMPRODUCT(F6:F17,'Output Produzione'!C31:C42)/SUM('Output Produzione'!C31:C42) -> 117.85183 | H34: =SUMPRODUCT(F6:F17,'Output Produzione'!C45:C56)/SUM('Output Produzione'!C45:C56) -> 118.10171

Sheet OPEX and CAPEX
B2: E-SMR | L2: Metanatore
B3: CAPEX [€/MW] | C3: CAPEX [€] | D3: OPEX [€/MWh] | E3: OPEX [€] | F3: Lifetime [y] | L3: CAPEX [€] | N3: OPEX [€/tonCO2] | O3: OPEX 0 [€] | P3: OPEX 1 [€] | Q3: OPEX 2 [€] | R3: OPEX 3 [€] | S3: Lifetime [y]
B4: 6050000 | C4: =354*B4 -> 2141700000 | D4: =31.8 -> 31.8 | E4: =354*8760*0.98*D4 -> 96640811 | F4: 60 | L4: =C7/30 -> 8190000 | N4: 55 | O4: =N4*'Output Produzione'!F3*0.088393 -> 2028488.6 | P4: =N4*'Output Produzione'!F17*0.088393 -> 2036590.2 | Q4: =N4*'Output Produzione'!F31*0.088393 -> 2064150.4 | R4: =N4*'Output Produzione'!F45*0.088393 -> 2032803.9 | S4: 20
B5: HTSE
B6: CAPEX [€/MW] | C6: CAPEX [€] | D6: OPEX [%CAPEX/year] | E6: OPEX [€] | F6: Lifetime [y]
B7: 780000 | C7: =15*21*B7 -> 245700000 | D7: 2.5 | E7: =D7/100*C7 -> 6142500 | F7: 20
B8: Compressor
B9: CAPEX [€/MW] | C9: CAPEX [€] | D9: OPEX [%CAPEX/year] | E9: OPEX [€] | F9: Lifetime [y]
B10: 1000000 | C10: =1.5*B10 -> 1500000 | D10: 1 | E10: =D10/100*C10 -> 15000 | F10: 10
B11: Storage
B12: CAPEX [€/Kg] | C12: CAPEX [€] | D12: OPEX [%CAPEX/year] | E12: OPEX [€] | F12: Lifetime [y]
B13: 490 | C13: =490*100000 -> 49000000 | D13: 1.5 | E13: =D13/100*C13 -> 735000 | F13: 20
B20: Turbine LM6000
B21: CAPEX [€/MW] | C21: CAPEX [€] | D21: OPEX [€/MW] | E21: OPEX [€] | F21: Lifetime [y]
C22: 23200000 | D22: =13930/2 -> 6965 | E22: =D22*47 -> 327355 | F22: 20

Sheet Base Case
B1: Scenario 0 | C1: Scenario 1 | D1: Scenario 2 | E1: Scenario 3 | H1: Scenario 0 | I1: Scenario 1 | J1: Scenario 2 | K1: Scenario 3 | N1: Initial CAPEX | T1: Tax rate (ires + irap) | V1: Discount Rate
A2: Energy to Community (MWh) | B2: =SUM('Output Produzione'!C3:C14) -> 369257.26 | C2: =SUM('Output Produzione'!C17:C28) -> 334190.92 | D2: =SUM('Output Produzione'!C31:C42) -> 292224.77 | E2: =SUM('Output Produzione'!C45:C56) -> 272576.69 | G2: Community price (€/MWh) | H2: ='Prezzi Energia Vari'!B31 -> 104.72089 | I2: ='Prezzi Energia Vari'!D31 -> 105.44537 | J2: ='Prezzi Energia Vari'!F31 -> 106.06665 | K2: ='Prezzi Energia Vari'!H31 -> 106.29154 | N2: ='OPEX and CAPEX'!C4+'OPEX and CAPEX'!C7+'OPEX and CAPEX'!C10+'OPEX and CAPEX'!C13+'OPEX and CAPEX'!L4+'OPEX and CAPEX'!C22 -> 2469290000 | T2: 0.279 | V2: 0.05
A3: Energy to Market (MWh) | B3: =SUM('Output Produzione'!D3:D14) -> 487559.49 | C3: =SUM('Output Produzione'!D17:D28) -> 477231.38 | D3: =SUM('Output Produzione'!D31:D42) -> 519155.54 | E3: =SUM('Output Produzione'!D45:D56) -> 579243.71 | G3: Market price (€/MWh) | H3: ='Prezzi Energia Vari'!B34 -> 116.35655 | I3: ='Prezzi Energia Vari'!D34 -> 117.16153 | J3: ='Prezzi Energia Vari'!F34 -> 117.85183 | K3: ='Prezzi Energia Vari'!H34 -> 118.10171
B5: Scenario 0 | R5: Scenario 1 | AG5: Scenario 2 | AV5: Scenario 3 | BJ5: Fine
B6: 0 | C6: 1 | D6: 2 | E6: 3 | F6: 4 | G6: 5 | H6: 6 | I6: 7 | J6: 8 | K6: 9 | L6: 10 | M6: 11 | N6: 12 | O6: 13 | P6: 14 | Q6: 15 | R6: 16 | S6: 17 | T6: 18 | U6: 19 | V6: 20 | W6: 21 | X6: 22 | Y6: 23 | Z6: 24 | AA6: 25 | AB6: 26 | AC6: 27 | AD6: 28 | AE6: 29 | AF6: 30 | AG6: 31 | AH6: 32 | AI6: 33 | AJ6: 34 | AK6: 35 | AL6: 36 | AM6: 37 | AN6: 38 | AO6: 39 | AP6: 40 | AQ6: 41 | AR6: 42 | AS6: 43 | AT6: 44 | AU6: 45 | AV6: 46 | AW6: 47 | AX6: 48 | AY6: 49 | AZ6: 50 | BA6: 51 | BB6: 52 | BC6: 53 | BD6: 54 | BE6: 55 | BF6: 56 | BG6: 57 | BH6: 58 | BI6: 59 | BJ6: 60
A7: Income Statement | B7: 2025 | C7: 2026 | D7: 2027 | E7: 2028 | F7: 2029 | G7: 2030 | H7: 2031 | I7: 2032 | J7: 2033 | K7: 2034 | L7: 2035 | M7: 2036 | N7: 2037 | O7: 2038 | P7: 2039 | Q7: 2040 | R7: 2041 | S7: 2042 | T7: 2043 | U7: 2044 | V7: 2045 | W7: 2046 | X7: 2047 | Y7: 2048 | Z7: 2049 | AA7: 2050 | AB7: 2051 | AC7: 2052 | AD7: 2053 | AE7: 2054 | AF7: 2055 | AG7: 2056 | AH7: 2057 | AI7: 2058 | AJ7: 2059 | AK7: 2060 | AL7: 2061 | AM7: 2062 | AN7: 2063 | AO7: 2064 | AP7: 2065 | AQ7: 2066 | AR7: 2067 | AS7: 2068 | AT7: 2069 | AU7: 2070 | AV7: 2071 | AW7: 2072 | AX7: 2073 | AY7: 2074 | AZ7: 2075 | BA7: 2076 | BB7: 2077 | BC7: 2078 | BD7: 2079 | BE7: 2080 | BF7: 2081 | BG7: 2082 | BH7: 2083 | BI7: 2084 | BJ7: 2085
A8: Electricity | C8: =($B$2*'Prezzi Energia Vari'!$B$31+$B$3*'Prezzi Energia Vari'!$B$34)*1.0063742415 -> 96007787 | D8: =C8*1.0063742415 -> 96619764 | E8: =D8*1.006374 -> 97235619 | F8: =E8*1.006374 -> 97855398 | G8: =F8*1.006374 -> 98479129 | H8: =G8*1.006374 -> 99106835 | I8: =H8*1.006374 -> 99738542 | J8: =I8*1.006374 -> 1.0037428e+08 | K8: =J8*1.006374 -> 1.0101406e+08 | L8: =K8*1.006374 -> 1.0165792e+08 | ... Q8: =P8*1.006374 -> 1.0493933e+08 | R8: =(C2*'Prezzi Energia Vari'!D31+C3*'Prezzi Energia Vari'!D34)*1.1*1.006374 -> 1.0090635e+08 | S8: =R8*1.006374 -> 1.0154953e+08 | T8: =S8*1.006374 -> 1.0219681e+08 | U8: =T8*1.006374 -> 1.0284821e+08 | V8: =U8*1.006374 -> 1.0350376e+08 | W8: =V8*1.006374 -> 1.041635e+08 | X8: =W8*1.006374 -> 1.0482743e+08 | Y8: =X8*1.006374 -> 1.054956e+08 | Z8: =Y8*1.006374 -> 1.0616803e+08 | ... AF8: =AE8*1.006374 -> 1.1029358e+08 | AG8: =(D2*'Prezzi Energia Vari'!F31+D3*'Prezzi Energia Vari'!F34)*1.1^2*1.006374 -> 1.122472e+08 | AH8: =AG8*1.006374 -> 1.1296266e+08 | AI8: =AH8*1.006374 -> 1.1368269e+08 | AJ8: =AI8*1.006374 -> 1.144073e+08 | AK8: =AJ8*1.006374 -> 1.1513653e+08 | AL8: =AK8*1.006374 -> 1.1587041e+08 | AM8: =AL8*1.006374 -> 1.1660897e+08 | AN8: =AM8*1.006374 -> 1.1735224e+08 | AO8: =AN8*1.006374 -> 1.1810024e+08 | ... AU8: =AT8*1.006374 -> 1.2268945e+08 | AV8: =(E2*'Prezzi Energia Vari'!H31+E3*'Prezzi Energia Vari'!H34)*1.1^3*1.006374 -> 1.3044197e+08 | AW8: =AV8*1.006374 -> 1.3127341e+08 | AX8: =AW8*1.006374 -> 1.3211015e+08 | AY8: =AX8*1.006374 -> 1.3295222e+08 | AZ8: =AY8*1.006374 -> 1.3379965e+08 | BA8: =AZ8*1.006374 -> 1.3465249e+08 | BB8: =BA8*1.006374 -> 1.3551077e+08 | BC8: =BB8*1.006374 -> 1.3637451e+08 | BD8: =BC8*1.006374 -> 1.3724376e+08 | ... BJ8: =BI8*1.006374 -> 1.4257687e+08
A9: Hydrogen | C9: ='Output Produzione'!$F$3*'Prezzi Energia Vari'!$B$24*(1-0.0175) -> 49193285 | D9: =C9*(1-0.0175) -> 48332402 | E9: =D9*(1-0.0175) -> 47486585 | F9: =E9*(1-0.0175) -> 46655570 | G9: =F9*(1-0.0175) -> 45839097 | H9: =G9*(1-0.0175) -> 45036913 | I9: =H9*(1-0.0175) -> 44248767 | J9: =I9*(1-0.0175) -> 43474414 | K9: =J9*(1-0.0175) -> 42713611 | ... Q9: =P9*(1-0.0175) -> 38420379 | R9: ='Output Produzione'!$F$17*'Prezzi Energia Vari'!$B$24*(1-0.0175)^R$6 -> 37898785 | S9: =R9*(1-0.0175) -> 37235556 | T9: =S9*(1-0.0175) -> 36583934 | U9: =T9*(1-0.0175) -> 35943715 | V9: =U9*(1-0.0175) -> 35314700 | W9: =V9*(1-0.00875) -> 35005696 | X9: =W9*(1-0.00875) -> 34699396 | Y9: =X9*(1-0.00875) -> 34395777 | Z9: =Y9*(1-0.00875) -> 34094814 | AA9: =Z9*(1-0.00875) -> 33796484 | AB9: =AA9*(1-0.00875) -> 33500765 | AC9: =AB9*(1-0.00875) -> 33207633 | AD9: =AC9*(1-0.00875) -> 32917066 | ... AF9: =AE9*(1-0.00875) -> 32343538 | AG9: ='Output Produzione'!$F$31*'Prezzi Energia Vari'!$B$24*(1-0.0175)^(AG6-15)*(1-0.00875)^(AG6-15) -> 33372918 | AH9: =AG9*(1-0.00875) -> 33080905 | AI9: =AH9*(1-0.00875) -> 32791447 | AJ9: =AI9*(1-0.00875) -> 32504522 | AK9: =AJ9*(1-0.00875) -> 32220107 | AL9: =AK9*(1-0.00875) -> 31938181 | AM9: =AL9*(1-0.00875) -> 31658722 | AN9: =AM9*(1-0.00875) -> 31381708 | AO9: =AN9*(1-0.00875) -> 31107118 | AP9: =AO9*(1-0.00875) -> 30834931 | AQ9: =AP9*1.006374 -> 31031473 | AR9: =AQ9*1.006374 -> 31229267 | AS9: =AR9*1.006374 -> 31428323 | AT9: =AS9*1.006374 -> 31628647 | AU9: =AT9*1.006374 -> 31830248 | AV9: ='Output Produzione'!$F$45*'Prezzi Energia Vari'!$B$24*(1-0.0175)^(AG6-15)*(1-0.00875)^(AG6-15+9)*1.006374^6 -> 31546673 | AW9: =AV9*1.006374 -> 31747751 | AX9: =AW9*1.006374 -> 31950111 | AY9: =AX9*1.006374 -> 32153761 | AZ9: =AY9*1.006374 -> 32358709 | BA9: =AZ9*1.006374 -> 32564964 | BB9: =BA9*1.006374 -> 32772533 | BC9: =BB9*1.006374 -> 32981425 | BD9: =BC9*1.006374 -> 33191649 | ... BJ9: =BI9*1.006374 -> 34481430
A10: Syngas | C10: ='Output Produzione'!$G$3*'Prezzi Energia Vari'!$B$27*(1-0.0175) -> 41031126 | D10: =C10*(1-0.0175) -> 40313082 | E10: =D10*(1-0.0175) -> 39607603 | F10: =E10*(1-0.0175) -> 38914470 | G10: =F10*(1-0.0175) -> 38233467 | H10: =G10*(1-0.0175) -> 37564381 | I10: =H10*(1-0.0175) -> 36907004 | J10: =I10*(1-0.0175) -> 36261132 | K10: =J10*(1-0.0175) -> 35626562 | ... Q10: =P10*(1-0.0175) -> 32045663 | R10: ='Output Produzione'!$G$17*'Prezzi Energia Vari'!$B$27*(1-0.0175)^R$6 -> 31492273 | S10: =R10*(1-0.0175) -> 30941158 | T10: =S10*(1-0.0175) -> 30399688 | U10: =T10*(1-0.0175) -> 29867694 | V10: =U10*(1-0.0175) -> 29345009 | W10: =V10*(1-0.00875) -> 29088240 | X10: =W10*(1-0.00875) -> 28833718 | Y10: =X10*(1-0.00875) -> 28581423 | Z10: =Y10*(1-0.00875) -> 28331336 | AA10: =Z10*(1-0.00875) -> 28083436 | AB10: =AA10*(1-0.00875) -> 27837706 | AC10: =AB10*(1-0.00875) -> 27594126 | AD10: =AC10*(1-0.00875) -> 27352678 | ... AF10: =AE10*(1-0.00875) -> 26876100 | AG10: ='Output Produzione'!$G$31*'Prezzi Energia Vari'!$B$27*(1-0.0175)^(AG6-15)*(1-0.00875)^(AG6-15) -> 27391234 | AH10: =AG10*(1-0.00875) -> 27151561 | AI10: =AH10*(1-0.00875) -> 26913985 | AJ10: =AI10*(1-0.00875) -> 26678487 | AK10: =AJ10*(1-0.00875) -> 26445051 | AL10: =AK10*(1-0.00875) -> 26213657 | AM10: =AL10*(1-0.00875) -> 25984287 | AN10: =AM10*(1-0.00875) -> 25756925 | AO10: =AN10*(1-0.00875) -> 25531551 | AP10: =AO10*(1-0.00875) -> 25308150 | AQ10: =AP10*1.006374 -> 25469465 | AR10: =AQ10*1.006374 -> 25631807 | AS10: =AR10*1.006374 -> 25795184 | AT10: =AS10*1.006374 -> 25959603 | AU10: =AT10*1.006374 -> 26125069 | AV10: ='Output Produzione'!$G$45*'Prezzi Energia Vari'!$B$27*(1-0.0175)^(AG6-15)*(1-0.00875)^(AG6-15+9)*1.006374^6 -> 26256026 | AW10: =AV10*1.006374 -> 26423382 | AX10: =AW10*1.006374 -> 26591805 | AY10: =AX10*1.006374 -> 26761301 | AZ10: =AY10*1.006374 -> 26931878 | BA10: =AZ10*1.006374 -> 27103541 | BB10: =BA10*1.006374 -> 27276299 | BC10: =BB10*1.006374 -> 27450158 | BD10: =BC10*1.006374 -> 27625126 | ... BJ10: =BI10*1.006374 -> 28698600
A11: Total operating revenues | C11: =C8+C9+C10 -> 1.862322e+08 | D11: =D8+D9+D10 -> 1.8526525e+08 | E11: =E8+E9+E10 -> 1.8432981e+08 | F11: =F8+F9+F10 -> 1.8342544e+08 | G11: =G8+G9+G10 -> 1.8255169e+08 | H11: =H8+H9+H10 -> 1.8170813e+08 | I11: =I8+I9+I10 -> 1.8089431e+08 | J11: =J8+J9+J10 -> 1.8010982e+08 | ... BJ11: =BJ8+BJ9+BJ10 -> 2.057569e+08
A12: SMR | C12: =-('OPEX and CAPEX'!$E$4)*0.97650215 -> -94369959 | D12: =C12*0.97650215 -> -92152468 | E12: =D12*0.97650215 -> -89987083 | F12: =E12*0.97650215 -> -87872580 | G12: =F12*0.97650215 -> -85807764 | H12: =G12*0.97650215 -> -83791466 | I12: =H12*0.97650215 -> -81822546 | J12: =I12*0.97650215 -> -79899892 | K12: =J12*0.97650215 -> -78022417 | ... Q12: =P12*0.97650215 -> -67648570 | R12: =-('OPEX and CAPEX'!$E$4)*0.7*0.993 -> -67175027 | S12: =R12*0.993 -> -66704802 | T12: =S12*0.993 -> -66237869 | U12: =T12*0.993 -> -65774204 | V12: =U12*0.993 -> -65313784 | W12: =V12*0.993 -> -64856588 | X12: =W12*0.993 -> -64402592 | Y12: =X12*0.993 -> -63951773 | Z12: =Y12*0.993 -> -63504111 | ... AF12: =AE12*0.993 -> -60883180 | AG12: =AF12 -> -60883180 | AH12: =AG12 -> -60883180 | AI12: =AH12 -> -60883180 | AJ12: =AI12 -> -60883180 | AK12: =AJ12 -> -60883180 | AL12: =AK12 -> -60883180 | AM12: =AL12 -> -60883180 | AN12: =AM12 -> -60883180 | ... BJ12: =BI12 -> -60883180
A13: Hydrogen System | C13: =-('OPEX and CAPEX'!$E$7+'OPEX and CAPEX'!$E$10+'OPEX and CAPEX'!$E$13)*0.97650215 -> -6730541.1 | D13: =C13*0.97650215 -> -6572387.8 | E13: =D13*0.97650215 -> -6417950.8 | F13: =E13*0.97650215 -> -6267142.8 | G13: =F13*0.97650215 -> -6119878.4 | H13: =G13*0.97650215 -> -5976074.4 | I13: =H13*0.97650215 -> -5835649.5 | J13: =I13*0.97650215 -> -5698524.3 | K13: =J13*0.97650215 -> -5564621.2 | ... Q13: =P13*0.97650215 -> -4824750.2 | R13: =-('OPEX and CAPEX'!$E$7+'OPEX and CAPEX'!$E$10+'OPEX and CAPEX'!$E$13)*0.7*0.993 -> -4790976.8 | S13: =R13*0.993 -> -4757439.9 | T13: =S13*0.993 -> -4724137.8 | U13: =T13*0.993 -> -4691068.9 | V13: =U13*0.993 -> -4658231.4 | W13: =V13*0.993 -> -4625623.8 | X13: =W13*0.993 -> -4593244.4 | Y13: =X13*0.993 -> -4561091.7 | Z13: =Y13*0.993 -> -4529164 | ... AF13: =AE13*0.993 -> -4342237.2 | AG13: =AF13 -> -4342237.2 | AH13: =AG13 -> -4342237.2 | AI13: =AH13 -> -4342237.2 | AJ13: =AI13 -> -4342237.2 | AK13: =AJ13 -> -4342237.2 | AL13: =AK13 -> -4342237.2 | AM13: =AL13 -> -4342237.2 | AN13: =AM13 -> -4342237.2 | ... BJ13: =BI13 -> -4342237.2
A14: Methanator | C14: =-('OPEX and CAPEX'!$O$4)*'OPEX and CAPEX'!N20 -> 0 | D14: =C14*'OPEX and CAPEX'!$N$20 -> 0 | E14: =D14*'OPEX and CAPEX'!$N$20 -> 0 | F14: =E14*'OPEX and CAPEX'!$N$20 -> 0 | G14: =F14*'OPEX and CAPEX'!$N$20 -> 0 | H14: =G14*'OPEX and CAPEX'!$N$20 -> 0 | I14: =H14*'OPEX and CAPEX'!$N$20 -> 0 | J14: =I14*'OPEX and CAPEX'!$N$20 -> 0 | K14: =J14*'OPEX and CAPEX'!$N$20 -> 0 | ... Q14: =P14*'OPEX and CAPEX'!$N$20 -> 0 | R14: =-('OPEX and CAPEX'!$P$4)*0.65*'OPEX and CAPEX'!$O$20 -> 0 | S14: =R14*'OPEX and CAPEX'!$O$20 -> 0 | T14: =S14*'OPEX and CAPEX'!$O$20 -> 0 | U14: =T14*'OPEX and CAPEX'!$O$20 -> 0 | V14: =U14*'OPEX and CAPEX'!$O$20 -> 0 | W14: =V14*'OPEX and CAPEX'!$O$20 -> 0 | X14: =W14*'OPEX and CAPEX'!$O$20 -> 0 | Y14: =X14*'OPEX and CAPEX'!$O$20 -> 0 | Z14: =Y14*'OPEX and CAPEX'!$O$20 -> 0 | ... AF14: =AE14*'OPEX and CAPEX'!$O$20 -> 0 | AG14: =-('OPEX and CAPEX'!$Q$4)*0.65*0.6933*'OPEX and CAPEX'!$P$20 -> 0 | AH14: =AG14*'OPEX and CAPEX'!$P$20 -> 0 | AI14: =AH14*'OPEX and CAPEX'!$P$20 -> 0 | AJ14: =AI14*'OPEX and CAPEX'!$P$20 -> 0 | AK14: =AJ14*'OPEX and CAPEX'!$P$20 -> 0 | AL14: =AK14*'OPEX and CAPEX'!$P$20 -> 0 | AM14: =AL14*'OPEX and CAPEX'!$P$20 -> 0 | AN14: =AM14*'OPEX and CAPEX'!$P$20 -> 0 | AO14: =AN14*'OPEX and CAPEX'!$P$20 -> 0 | ... AU14: =AT14*'OPEX and CAPEX'!$P$20 -> 0 | AV14: =-('OPEX and CAPEX'!$R$4)*0.65*0.6933*0.7222*'OPEX and CAPEX'!$Q$20 -> 0 | AW14: =-('OPEX and CAPEX'!$R$4)*0.65*0.6933*0.7222*'OPEX and CAPEX'!$Q$20 -> 0 | AX14: =-('OPEX and CAPEX'!$R$4)*0.65*0.6933*0.7222*'OPEX and CAPEX'!$Q$20 -> 0 | AY14: =-('OPEX and CAPEX'!$R$4)*0.65*0.6933*0.7222*'OPEX and CAPEX'!$Q$20 -> 0 | AZ14: =-('OPEX and CAPEX'!$R$4)*0.65*0.6933*0.7222*'OPEX and CAPEX'!$Q$20 -> 0 | BA14: =-('OPEX and CAPEX'!$R$4)*0.65*0.6933*0.7222*'OPEX and CAPEX'!$Q$20 -> 0 | BB14: =-('OPEX and CAPEX'!$R$4)*0.65*0.6933*0.7222*'OPEX and CAPEX'!$Q$20 -> 0 | BC14: =-('OPEX and CAPEX'!$R$4)*0.65*0.6933*0.7222*'OPEX and CAPEX'!$Q$20 -> 0 | ... BJ14: =-('OPEX and CAPEX'!$R$4)*0.65*0.6933*0.7222*'OPEX and CAPEX'!$Q$20 -> 0
A15: Turbine | C15: =-'OPEX and CAPEX'!$E$22 -> -327355 | D15: =-'OPEX and CAPEX'!$E$22 -> -327355 | E15: =-'OPEX and CAPEX'!$E$22 -> -327355 | F15: =-'OPEX and CAPEX'!$E$22 -> -327355 | G15: =-'OPEX and CAPEX'!$E$22 -> -327355 | H15: =-'OPEX and CAPEX'!$E$22 -> -327355 | I15: =-'OPEX and CAPEX'!$E$22 -> -327355 | J15: =-'OPEX and CAPEX'!$E$22 -> -327355 | ... BJ15: =-'OPEX and CAPEX'!$E$22 -> -327355
A16: OpEx | C16: =C12+C13+C14+C15 -> -1.0142786e+08 | D16: =D12+D13+D14+D15 -> -99052211 | E16: =E12+E13+E14+E15 -> -96732389 | F16: =F12+F13+F14+F15 -> -94467078 | G16: =G12+G13+G14+G15 -> -92254997 | H16: =H12+H13+H14+H15 -> -90094895 | I16: =I12+I13+I14+I15 -> -87985551 | J16: =J12+J13+J14+J15 -> -85925772 | ... BJ16: =BJ12+BJ13+BJ14+BJ15 -> -65552773
A17: Investment | B17: =N2 -> 2469290000 | W17: =('OPEX and CAPEX'!C7+'OPEX and CAPEX'!C10+'OPEX and CAPEX'!C13+'OPEX and CAPEX'!L4)*0.7+'OPEX and CAPEX'!C22 -> 236273000 | AQ17: =W17*0.85+'OPEX and CAPEX'!C22 -> 224032050
A18: EBITDA | C18: =C11+C16 -> 84804343 | D18: =D11+D16 -> 86213037 | E18: =E11+E16 -> 87597417 | F18: =F11+F16 -> 88958360 | G18: =G11+G16 -> 90296696 | H18: =H11+H16 -> 91613234 | I18: =I11+I16 -> 92908762 | J18: =J11+J16 -> 94184049 | ... BJ18: =BJ11+BJ16 -> 1.4020413e+08
A19: Depreciation | C19: =-('OPEX and CAPEX'!C4/'OPEX and CAPEX'!F4+'OPEX and CAPEX'!C7/'OPEX and CAPEX'!F7+'OPEX and CAPEX'!C10/'OPEX and CAPEX'!F10+'OPEX and CAPEX'!C13/'OPEX and CAPEX'!F13+'OPEX and CAPEX'!L4/'OPEX and CAPEX'!S4) -> -50989500 | D19: =$C$19 -> -50989500 | E19: =$C$19 -> -50989500 | F19: =$C$19 -> -50989500 | G19: =$C$19 -> -50989500 | H19: =$C$19 -> -50989500 | I19: =$C$19 -> -50989500 | J19: =$C$19 -> -50989500 | K19: =$C$19 -> -50989500 | ... BJ19: =$C$19 -> -50989500
A20: EBIT | C20: =C18+C19 -> 33814843 | D20: =D18+D19 -> 35223537 | E20: =E18+E19 -> 36607917 | F20: =F18+F19 -> 37968860 | G20: =G18+G19 -> 39307196 | H20: =H18+H19 -> 40623734 | I20: =I18+I19 -> 41919262 | J20: =J18+J19 -> 43194549 | ... BJ20: =BJ18+BJ19 -> 89214626
A21: Taxes | C21: =-$T$2*C20 -> -9434341.2 | D21: =-$T$2*D20 -> -9827366.8 | E21: =-$T$2*E20 -> -10213609 | F21: =-$T$2*F20 -> -10593312 | G21: =-$T$2*G20 -> -10966708 | H21: =-$T$2*H20 -> -11334022 | I21: =-$T$2*I20 -> -11695474 | J21: =-$T$2*J20 -> -12051279 | ... BJ21: =-$T$2*BJ20 -> -24890881
A22: Net Income | C22: =C20+C21 -> 24380502 | D22: =D20+D21 -> 25396170 | E22: =E20+E21 -> 26394308 | F22: =F20+F21 -> 27375548 | G22: =G20+G21 -> 28340488 | H22: =H20+H21 -> 29289712 | I22: =I20+I21 -> 30223788 | J22: =J20+J21 -> 31143270 | ... BJ22: =BJ20+BJ21 -> 64323746
A24: Present value of costs | B24: =N2 -> 2469290000 | C24: =(ABS(C16)+C17)/(1+$V$2)^C6 -> 96597957 | D24: =(ABS(D16)+D17)/(1+$V$2)^D6 -> 89843275 | E24: =(ABS(E16)+E17)/(1+$V$2)^E6 -> 83561075 | F24: =(ABS(F16)+F17)/(1+$V$2)^F6 -> 77718299 | G24: =(ABS(G16)+G17)/(1+$V$2)^G6 -> 72284204 | H24: =(ABS(H16)+H17)/(1+$V$2)^H6 -> 67230198 | I24: =(ABS(I16)+I17)/(1+$V$2)^I6 -> 62529688 | J24: =(ABS(J16)+J17)/(1+$V$2)^J6 -> 58157945 | ... BJ24: =(ABS(BJ16)+BJ17)/(1+$V$2)^BJ6 -> 3509402 | BK24: =SUM(B24:BJ24) -> 4.0793898e+09
A25: Present value of energy | C25: =(($B$3+$B$2+'Output Produzione'!$F$3+'Output Produzione'!$G$3)*1000)/((1+$V$2)^C6) -> 1.379115e+09 | D25: =(($B$3+$B$2+'Output Produzione'!$F$3+'Output Produzione'!$G$3)/(1+$V$2)^D6)*1000 -> 1.3134429e+09 | E25: =(($B$3+$B$2+'Output Produzione'!$F$3+'Output Produzione'!$G$3)/(1+$V$2)^E6)*1000 -> 1.250898e+09 | F25: =(($B$3+$B$2+'Output Produzione'!$F$3+'Output Produzione'!$G$3)/(1+$V$2)^F6)*1000 -> 1.1913314e+09 | G25: =(($B$3+$B$2+'Output Produzione'!$F$3+'Output Produzione'!$G$3)/(1+$V$2)^G6)*1000 -> 1.1346013e+09 | H25: =(($B$3+$B$2+'Output Produzione'!$F$3+'Output Produzione'!$G$3)/(1+$V$2)^H6)*1000 -> 1.0805727e+09 | I25: =(($B$3+$B$2+'Output Produzione'!$F$3+'Output Produzione'!$G$3)/(1+$V$2)^I6)*1000 -> 1.0291169e+09 | J25: =(($B$3+$B$2+'Output Produzione'!$F$3+'Output Produzione'!$G$3)/(1+$V$2)^J6)*1000 -> 9.8011129e+08 | K25: =(($B$3+$B$2+'Output Produzione'!$F$3+'Output Produzione'!$G$3)/(1+$V$2)^K6)*1000 -> 9.3343932e+08 | ... Q25: =(($B$3+$B$2+'Output Produzione'!$F$3+'Output Produzione'!$G$3)/(1+$V$2)^Q6)*1000 -> 6.9654679e+08 | R25: =(($C$3+$C$2+'Output Produzione'!$F$17+'Output Produzione'!$G$17)/(1+$V$2)^R6)*1000 -> 6.4336436e+08 | S25: =(($C$3+$C$2+'Output Produzione'!$F$17+'Output Produzione'!$G$17)/(1+$V$2)^S6)*1000 -> 6.1272796e+08 | T25: =(($C$3+$C$2+'Output Produzione'!$F$17+'Output Produzione'!$G$17)/(1+$V$2)^T6)*1000 -> 5.8355044e+08 | U25: =(($C$3+$C$2+'Output Produzione'!$F$17+'Output Produzione'!$G$17)/(1+$V$2)^U6)*1000 -> 5.5576232e+08 | V25: =(($C$3+$C$2+'Output Produzione'!$F$17+'Output Produzione'!$G$17)/(1+$V$2)^V6)*1000 -> 5.2929745e+08 | W25: =(($C$3+$C$2+'Output Produzione'!$F$17+'Output Produzione'!$G$17)/(1+$V$2)^W6)*1000 -> 5.0409281e+08 | X25: =(($C$3+$C$2+'Output Produzione'!$F$17+'Output Produzione'!$G$17)/(1+$V$2)^X6)*1000 -> 4.8008839e+08 | Y25: =(($C$3+$C$2+'Output Produzione'!$F$17+'Output Produzione'!$G$17)/(1+$V$2)^Y6)*1000 -> 4.5722704e+08 | ... AF25: =(($C$3+$C$2+'Output Produzione'!$F$17+'Output Produzione'!$G$17)/(1+$V$2)^AF6)*1000 -> 3.2494272e+08 | AG25: =(($D$3+$D$2+'Output Produzione'!$F$31+'Output Produzione'!$G$31)/(1+$V$2)^AG6)*1000 -> 3.107513e+08 | AH25: =(($D$3+$D$2+'Output Produzione'!$F$31+'Output Produzione'!$G$31)/(1+$V$2)^AH6)*1000 -> 2.9595362e+08 | AI25: =(($D$3+$D$2+'Output Produzione'!$F$31+'Output Produzione'!$G$31)/(1+$V$2)^AI6)*1000 -> 2.8186059e+08 | AJ25: =(($D$3+$D$2+'Output Produzione'!$F$31+'Output Produzione'!$G$31)/(1+$V$2)^AJ6)*1000 -> 2.6843866e+08 | AK25: =(($D$3+$D$2+'Output Produzione'!$F$31+'Output Produzione'!$G$31)/(1+$V$2)^AK6)*1000 -> 2.5565586e+08 | AL25: =(($D$3+$D$2+'Output Produzione'!$F$31+'Output Produzione'!$G$31)/(1+$V$2)^AL6)*1000 -> 2.4348178e+08 | AM25: =(($D$3+$D$2+'Output Produzione'!$F$31+'Output Produzione'!$G$31)/(1+$V$2)^AM6)*1000 -> 2.3188741e+08 | AN25: =(($D$3+$D$2+'Output Produzione'!$F$31+'Output Produzione'!$G$31)/(1+$V$2)^AN6)*1000 -> 2.2084515e+08 | ... AU25: =(($D$3+$D$2+'Output Produzione'!$F$31+'Output Produzione'!$G$31)/(1+$V$2)^AU6)*1000 -> 1.5695052e+08 | AV25: =(($E$3+$E$2+'Output Produzione'!$F$45+'Output Produzione'!$G$45)/(1+$V$2)^AV6)*1000 -> 1.5305478e+08 | AW25: =(($E$3+$E$2+'Output Produzione'!$F$45+'Output Produzione'!$G$45)/(1+$V$2)^AW6)*1000 -> 1.4576646e+08 | AX25: =(($E$3+$E$2+'Output Produzione'!$F$45+'Output Produzione'!$G$45)/(1+$V$2)^AX6)*1000 -> 1.388252e+08 | AY25: =(($E$3+$E$2+'Output Produzione'!$F$45+'Output Produzione'!$G$45)/(1+$V$2)^AY6)*1000 -> 1.3221447e+08 | AZ25: =(($E$3+$E$2+'Output Produzione'!$F$45+'Output Produzione'!$G$45)/(1+$V$2)^AZ6)*1000 -> 1.2591855e+08 | BA25: =(($E$3+$E$2+'Output Produzione'!$F$45+'Output Produzione'!$G$45)/(1+$V$2)^BA6)*1000 -> 1.1992242e+08 | BB25: =(($E$3+$E$2+'Output Produzione'!$F$45+'Output Produzione'!$G$45)/(1+$V$2)^BB6)*1000 -> 1.1421183e+08 | BC25: =(($E$3+$E$2+'Output Produzione'!$F$45+'Output Produzione'!$G$45)/(1+$V$2)^BC6)*1000 -> 1.0877317e+08 | ... BJ25: =(($E$3+$E$2+'Output Produzione'!$F$45+'Output Produzione'!$G$45)/(1+$V$2)^BJ6)*1000 -> 77303064 | BK25: =SUM(C25:BJ25) -> 2.7097132e+10
A26: LCOE (€/kWh) | B26: =BK24/BK25 -> 0.15054692
B27: Scenario 0 | Q27: Scenario 1 | AF27: Scenario 2 | AU27: Scenario 3 | BJ27: Fine
B28: 0 | C28: 1 | D28: 2 | E28: 3 | F28: 4 | G28: 5 | H28: 6 | I28: 7 | J28: 8 | K28: 9 | L28: 10 | M28: 11 | N28: 12 | O28: 13 | P28: 14 | Q28: 15 | R28: 16 | S28: 17 | T28: 18 | U28: 19 | V28: 20 | W28: 21 | X28: 22 | Y28: 23 | Z28: 24 | AA28: 25 | AB28: 26 | AC28: 27 | AD28: 28 | AE28: 29 | AF28: 30 | AG28: 31 | AH28: 32 | AI28: 33 | AJ28: 34 | AK28: 35 | AL28: 36 | AM28: 37 | AN28: 38 | AO28: 39 | AP28: 40 | AQ28: 41 | AR28: 42 | AS28: 43 | AT28: 44 | AU28: 45 | AV28: 46 | AW28: 47 | AX28: 48 | AY28: 49 | AZ28: 50 | BA28: 51 | BB28: 52 | BC28: 53 | BD28: 54 | BE28: 55 | BF28: 56 | BG28: 57 | BH28: 58 | BI28: 59 | BJ28: 60
A29: CF Statement | B29: 2025 | C29: 2026 | D29: 2027 | E29: 2028 | F29: 2029 | G29: 2030 | H29: 2031 | I29: 2032 | J29: 2033 | K29: 2034 | L29: 2035 | M29: 2036 | N29: 2037 | O29: 2038 | P29: 2039 | Q29: 2040 | R29: 2041 | S29: 2042 | T29: 2043 | U29: 2044 | V29: 2045 | W29: 2046 | X29: 2047 | Y29: 2048 | Z29: 2049 | AA29: 2050 | AB29: 2051 | AC29: 2052 | AD29: 2053 | AE29: 2054 | AF29: 2055 | AG29: 2056 | AH29: 2057 | AI29: 2058 | AJ29: 2059 | AK29: 2060 | AL29: 2061 | AM29: 2062 | AN29: 2063 | AO29: 2064 | AP29: 2065 | AQ29: 2066 | AR29: 2067 | AS29: 2068 | AT29: 2069 | AU29: 2070 | AV29: 2071 | AW29: 2072 | AX29: 2073 | AY29: 2074 | AZ29: 2075 | BA29: 2076 | BB29: 2077 | BC29: 2078 | BD29: 2079 | BE29: 2080 | BF29: 2081 | BG29: 2082 | BH29: 2083 | BI29: 2084 | BJ29: 2085
A30: EBITDA | C30: =C18 -> 84804343 | D30: =D18 -> 86213037 | E30: =E18 -> 87597417 | F30: =F18 -> 88958360 | G30: =G18 -> 90296696 | H30: =H18 -> 91613234 | I30: =I18 -> 92908762 | J30: =J18 -> 94184049 | ... BJ30: =BJ18 -> 1.4020413e+08
A31: Investment | B31: =-N2 -> -2469290000 | C31: =-C17 -> 0 | D31: =-D17 -> 0 | E31: =-E17 -> 0 | F31: =-F17 -> 0 | G31: =-G17 -> 0 | H31: =-H17 -> 0 | I31: =-I17 -> 0 | J31: =-J17 -> 0 | ... BJ31: =-BJ17 -> 0
A32: Taxes | C32: =C21 -> -9434341.2 | D32: =D21 -> -9827366.8 | E32: =E21 -> -10213609 | F32: =F21 -> -10593312 | G32: =G21 -> -10966708 | H32: =H21 -> -11334022 | I32: =I21 -> -11695474 | J32: =J21 -> -12051279 | ... BJ32: =BJ21 -> -24890881
A33: Cash Flow | B33: =SUM(B30:B32) -> -2469290000 | C33: =SUM(C30:C32) -> 75370002 | D33: =SUM(D30:D32) -> 76385670 | E33: =SUM(E30:E32) -> 77383808 | F33: =SUM(F30:F32) -> 78365048 | G33: =SUM(G30:G32) -> 79329988 | H33: =SUM(H30:H32) -> 80279212 | I33: =SUM(I30:I32) -> 81213288 | ... BJ33: =SUM(BJ30:BJ32) -> 1.1531325e+08
A34: Cumulative Cash flow | B34: =B33 -> -2469290000 | C34: =C33+B34 -> -2.39392e+09 | D34: =D33+C34 -> -2.3175343e+09 | E34: =E33+D34 -> -2.2401505e+09 | F34: =F33+E34 -> -2.1617855e+09 | G34: =G33+F34 -> -2.0824555e+09 | H34: =H33+G34 -> -2.0021763e+09 | I34: =I33+H34 -> -1.920963e+09 | J34: =J33+I34 -> -1.8388302e+09 | ... BJ34: =BJ33+BI34 -> 2.6315547e+09
A36: Discounted CF | C36: =C33/(1+$V$2)^C28 -> 71780954 | D36: =D33/(1+$V$2)^D28 -> 69284055 | E36: =E33/(1+$V$2)^E28 -> 66847043 | F36: =F33/(1+$V$2)^F28 -> 64471119 | G36: =G33/(1+$V$2)^G28 -> 62157121 | H36: =H33/(1+$V$2)^H28 -> 59905584 | I36: =I33/(1+$V$2)^I28 -> 57716768 | J36: =J33/(1+$V$2)^J28 -> 55590691 | ... BJ36: =BJ33/(1+$V$2)^BJ28 -> 6173355
A37: S DCF | B37: =SUM(C36:BJ36) -> 1.5057853e+09
A38: Initial Investment | B38: =B31 -> -2469290000
A39: NPV | B39: =B37+B38 -> -9.6350473e+08
A40: IRR | B40: =IRR(B33:BJ33) -> 0.025814539

Sheet Full Electric
B1: Scenario 0 | C1: Scenario 1 | D1: Scenario 2 | E1: Scenario 3 | H1: Scenario 0 | I1: Scenario 1 | J1: Scenario 2 | K1: Scenario 3 | N1: Initial CAPEX | T1: Tax rate (ires + irap) | V1: Discount Rate
A2: Energy to Community (MWh) | B2: =SUM('Output Produzione'!C3:C14) -> 369257.26 | C2: =SUM('Output Produzione'!C17:C28) -> 334190.92 | D2: =SUM('Output Produzione'!C31:C42) -> 292224.77 | E2: =SUM('Output Produzione'!C45:C56) -> 272576.69 | G2: Community price (€/MWh) | H2: ='Prezzi Energia Vari'!B31 -> 104.72089 | I2: ='Prezzi Energia Vari'!D31 -> 105.44537 | J2: ='Prezzi Energia Vari'!F31 -> 106.06665 | K2: ='Prezzi Energia Vari'!H31 -> 106.29154 | N2: ='OPEX and CAPEX'!C4 -> 2141700000 | T2: 0.279 | V2: 0.05
A3: Energy to Market (MWh) | B3: =354*0.98*8760-B2 -> 2669761.9 | C3: =354*0.98*8760-C2 -> 2704828.3 | D3: =354*0.98*8760-D2 -> 2746794.4 | E3: =354*0.98*8760-E2 -> 2766442.5 | G3: Market price (€/MWh) | H3: ='Prezzi Energia Vari'!B34 -> 116.35655 | I3: ='Prezzi Energia Vari'!D34 -> 117.16153 | J3: ='Prezzi Energia Vari'!F34 -> 117.85183 | K3: ='Prezzi Energia Vari'!H34 -> 118.10171
B5: Scenario 0 | R5: Scenario 1 | AG5: Scenario 2 | AV5: Scenario 3 | BJ5: Fine
B6: 0 | C6: 1 | D6: 2 | E6: 3 | F6: 4 | G6: 5 | H6: 6 | I6: 7 | J6: 8 | K6: 9 | L6: 10 | M6: 11 | N6: 12 | O6: 13 | P6: 14 | Q6: 15 | R6: 16 | S6: 17 | T6: 18 | U6: 19 | V6: 20 | W6: 21 | X6: 22 | Y6: 23 | Z6: 24 | AA6: 25 | AB6: 26 | AC6: 27 | AD6: 28 | AE6: 29 | AF6: 30 | AG6: 31 | AH6: 32 | AI6: 33 | AJ6: 34 | AK6: 35 | AL6: 36 | AM6: 37 | AN6: 38 | AO6: 39 | AP6: 40 | AQ6: 41 | AR6: 42 | AS6: 43 | AT6: 44 | AU6: 45 | AV6: 46 | AW6: 47 | AX6: 48 | AY6: 49 | AZ6: 50 | BA6: 51 | BB6: 52 | BC6: 53 | BD6: 54 | BE6: 55 | BF6: 56 | BG6: 57 | BH6: 58 | BI6: 59 | BJ6: 60
A7: Income Statement | B7: 2025 | C7: 2026 | D7: 2027 | E7: 2028 | F7: 2029 | G7: 2030 | H7: 2031 | I7: 2032 | J7: 2033 | K7: 2034 | L7: 2035 | M7: 2036 | N7: 2037 | O7: 2038 | P7: 2039 | Q7: 2040 | R7: 2041 | S7: 2042 | T7: 2043 | U7: 2044 | V7: 2045 | W7: 2046 | X7: 2047 | Y7: 2048 | Z7: 2049 | AA7: 2050 | AB7: 2051 | AC7: 2052 | AD7: 2053 | AE7: 2054 | AF7: 2055 | AG7: 2056 | AH7: 2057 | AI7: 2058 | AJ7: 2059 | AK7: 2060 | AL7: 2061 | AM7: 2062 | AN7: 2063 | AO7: 2064 | AP7: 2065 | AQ7: 2066 | AR7: 2067 | AS7: 2068 | AT7: 2069 | AU7: 2070 | AV7: 2071 | AW7: 2072 | AX7: 2073 | AY7: 2074 | AZ7: 2075 | BA7: 2076 | BB7: 2077 | BC7: 2078 | BD7: 2079 | BE7: 2080 | BF7: 2081 | BG7: 2082 | BH7: 2083 | BI7: 2084 | BJ7: 2085
A8: Electricity | C8: =($B$2*'Prezzi Energia Vari'!$B$31+$B$3*'Prezzi Energia Vari'!$B$34)*1.0063742415 -> 3.5153983e+08 | D8: =C8*1.0063742415 -> 3.5378063e+08 | E8: =D8*1.006374 -> 3.5603563e+08 | F8: =E8*1.006374 -> 3.58305e+08 | G8: =F8*1.006374 -> 3.6058884e+08 | H8: =G8*1.006374 -> 3.6288723e+08 | I8: =H8*1.006374 -> 3.6520027e+08 | J8: =I8*1.006374 -> 3.6752806e+08 | K8: =J8*1.006374 -> 3.6987068e+08 | L8: =K8*1.006374 -> 3.7222824e+08 | ... Q8: =P8*1.006374 -> 3.8424335e+08 | R8: =(C2*'Prezzi Energia Vari'!D31+C3*'Prezzi Energia Vari'!D34)*1.1*1.006374 -> 3.8982377e+08 | S8: =R8*1.006374 -> 3.9230851e+08 | T8: =S8*1.006374 -> 3.9480908e+08 | U8: =T8*1.006374 -> 3.9732559e+08 | V8: =U8*1.006374 -> 3.9985815e+08 | W8: =V8*1.006374 -> 4.0240684e+08 | X8: =W8*1.006374 -> 4.0497178e+08 | Y8: =X8*1.006374 -> 4.0755307e+08 | Z8: =Y8*1.006374 -> 4.1015082e+08 | ... AF8: =AE8*1.006374 -> 4.2608871e+08 | AG8: =(D2*'Prezzi Energia Vari'!F31+D3*'Prezzi Energia Vari'!F34)*1.1^2*1.006374 -> 4.3193488e+08 | AH8: =AG8*1.006374 -> 4.3468803e+08 | AI8: =AH8*1.006374 -> 4.3745873e+08 | AJ8: =AI8*1.006374 -> 4.402471e+08 | AK8: =AJ8*1.006374 -> 4.4305323e+08 | AL8: =AK8*1.006374 -> 4.4587725e+08 | AM8: =AL8*1.006374 -> 4.4871927e+08 | AN8: =AM8*1.006374 -> 4.5157941e+08 | AO8: =AN8*1.006374 -> 4.5445778e+08 | ... AU8: =AT8*1.006374 -> 4.7211738e+08 | AV8: =(E2*'Prezzi Energia Vari'!H31+E3*'Prezzi Energia Vari'!H34)*1.1^3*1.006374 -> 4.7644661e+08 | AW8: =AV8*1.006374 -> 4.7948348e+08 | AX8: =AW8*1.006374 -> 4.8253971e+08 | AY8: =AX8*1.006374 -> 4.8561542e+08 | AZ8: =AY8*1.006374 -> 4.8871073e+08 | BA8: =AZ8*1.006374 -> 4.9182577e+08 | BB8: =BA8*1.006374 -> 4.9496067e+08 | BC8: =BB8*1.006374 -> 4.9811555e+08 | BD8: =BC8*1.006374 -> 5.0129054e+08 | ... BJ8: =BI8*1.006374 -> 5.2077e+08
A9: Hydrogen
A10: Syngas
A11: Total operating revenues | C11: =C8+C9+C10 -> 3.5153983e+08 | D11: =D8+D9+D10 -> 3.5378063e+08 | E11: =E8+E9+E10 -> 3.5603563e+08 | F11: =F8+F9+F10 -> 3.58305e+08 | G11: =G8+G9+G10 -> 3.6058884e+08 | H11: =H8+H9+H10 -> 3.6288723e+08 | I11: =I8+I9+I10 -> 3.6520027e+08 | J11: =J8+J9+J10 -> 3.6752806e+08 | ... BJ11: =BJ8+BJ9+BJ10 -> 5.2077e+08
A12: SMR | C12: =-('OPEX and CAPEX'!$E$4)*0.97650215 -> -94369959 | D12: =C12*0.97650215 -> -92152468 | E12: =D12*0.97650215 -> -89987083 | F12: =E12*0.97650215 -> -87872580 | G12: =F12*0.97650215 -> -85807764 | H12: =G12*0.97650215 -> -83791466 | I12: =H12*0.97650215 -> -81822546 | J12: =I12*0.97650215 -> -79899892 | K12: =J12*0.97650215 -> -78022417 | ... Q12: =P12*0.97650215 -> -67648570 | R12: =-('OPEX and CAPEX'!$E$4)*0.7*0.993 -> -67175027 | S12: =R12*0.993 -> -66704802 | T12: =S12*0.993 -> -66237869 | U12: =T12*0.993 -> -65774204 | V12: =U12*0.993 -> -65313784 | W12: =V12*0.993 -> -64856588 | X12: =W12*0.993 -> -64402592 | Y12: =X12*0.993 -> -63951773 | Z12: =Y12*0.993 -> -63504111 | ... AF12: =AE12*0.993 -> -60883180 | AG12: =AF12 -> -60883180 | AH12: =AG12 -> -60883180 | AI12: =AH12 -> -60883180 | AJ12: =AI12 -> -60883180 | AK12: =AJ12 -> -60883180 | AL12: =AK12 -> -60883180 | AM12: =AL12 -> -60883180 | AN12: =AM12 -> -60883180 | ... BJ12: =BI12 -> -60883180
A13: Hydrogen System
A14: Methanator
A15: OpEx | C15: =C12+C13+C14 -> -94369959 | D15: =D12+D13+D14 -> -92152468 | E15: =E12+E13+E14 -> -89987083 | F15: =F12+F13+F14 -> -87872580 | G15: =G12+G13+G14 -> -85807764 | H15: =H12+H13+H14 -> -83791466 | I15: =I12+I13+I14 -> -81822546 | J15: =J12+J13+J14 -> -79899892 | ... BJ15: =BJ12+BJ13+BJ14 -> -60883180
A16: Investment | B16: =N2 -> 2141700000
A17: EBITDA | C17: =C11+C15 -> 2.5716987e+08 | D17: =D11+D15 -> 2.6162816e+08 | E17: =E11+E15 -> 2.6604855e+08 | F17: =F11+F15 -> 2.7043242e+08 | G17: =G11+G15 -> 2.7478107e+08 | H17: =H11+H15 -> 2.7909577e+08 | I17: =I11+I15 -> 2.8337773e+08 | J17: =J11+J15 -> 2.8762817e+08 | ... BJ17: =BJ11+BJ15 -> 4.5988682e+08
A18: Depreciation | C18: =-B16/60 -> -35695000 | D18: =$C$18 -> -35695000 | E18: =$C$18 -> -35695000 | F18: =$C$18 -> -35695000 | G18: =$C$18 -> -35695000 | H18: =$C$18 -> -35695000 | I18: =$C$18 -> -35695000 | J18: =$C$18 -> -35695000 | K18: =$C$18 -> -35695000 | ... BJ18: =$C$18 -> -35695000
A19: EBIT | C19: =C17+C18 -> 2.2147487e+08 | D19: =D17+D18 -> 2.2593316e+08 | E19: =E17+E18 -> 2.3035355e+08 | F19: =F17+F18 -> 2.3473742e+08 | G19: =G17+G18 -> 2.3908607e+08 | H19: =H17+H18 -> 2.4340077e+08 | I19: =I17+I18 -> 2.4768273e+08 | J19: =J17+J18 -> 2.5193317e+08 | ... BJ19: =BJ17+BJ18 -> 4.2419182e+08
A20: Taxes | C20: =-$T$2*C19 -> -61791490 | D20: =-$T$2*D19 -> -63035353 | E20: =-$T$2*E19 -> -64268640 | F20: =-$T$2*F19 -> -65491740 | G20: =-$T$2*G19 -> -66705015 | H20: =-$T$2*H19 -> -67908813 | I20: =-$T$2*I19 -> -69103481 | J20: =-$T$2*J19 -> -70289354 | ... BJ20: =-$T$2*BJ19 -> -1.1834952e+08
A21: Net Income | C21: =C19+C20 -> 1.5968338e+08 | D21: =D19+D20 -> 1.6289781e+08 | E21: =E19+E20 -> 1.6608491e+08 | F21: =F19+F20 -> 1.6924568e+08 | G21: =G19+G20 -> 1.7238106e+08 | H21: =H19+H20 -> 1.7549195e+08 | I21: =I19+I20 -> 1.7857925e+08 | J21: =J19+J20 -> 1.8164381e+08 | ... BJ21: =BJ19+BJ20 -> 3.058423e+08
A23: Present value of costs | B23: =N2 -> 2141700000 | C23: =(ABS(C15))/(1+$V$2)^C6 -> 89876152 | D23: =(ABS(D15))/(1+$V$2)^D6 -> 83585005 | E23: =(ABS(E15))/(1+$V$2)^E6 -> 77734226 | F23: =(ABS(F15))/(1+$V$2)^F6 -> 72292989 | G23: =(ABS(G15))/(1+$V$2)^G6 -> 67232628 | H23: =(ABS(H15))/(1+$V$2)^H6 -> 62526482 | I23: =(ABS(I15))/(1+$V$2)^I6 -> 58149756 | J23: =(ABS(J15))/(1+$V$2)^J6 -> 54079392 | ... BJ23: =(ABS(BJ15))/(1+$V$2)^BJ6 -> 3259413 | BK23: =SUM(B23:BJ23) -> 3.5313747e+09
A24: Present value of energy | C24: =($B$3+$B$2)*1000/((1+$V$2)^C6) -> 2894304000 | D24: =($B$3+$B$2)*1000/((1+$V$2)^D6) -> 2756480000 | E24: =($B$3+$B$2)*1000/((1+$V$2)^E6) -> 2.625219e+09 | F24: =($B$3+$B$2)*1000/((1+$V$2)^F6) -> 2.5002086e+09 | G24: =($B$3+$B$2)*1000/((1+$V$2)^G6) -> 2.3811511e+09 | H24: =($B$3+$B$2)*1000/((1+$V$2)^H6) -> 2.2677629e+09 | I24: =($B$3+$B$2)*1000/((1+$V$2)^I6) -> 2.1597742e+09 | J24: =($B$3+$B$2)*1000/((1+$V$2)^J6) -> 2.0569278e+09 | ... BJ24: =($B$3+$B$2)*1000/((1+$V$2)^BJ6) -> 1.6269548e+08 | BK24: =SUM(C24:BJ24) -> 5.7526474e+10
A25: LCOE (€/kWh) | B25: =BK23/BK24 -> 0.061386949
B26: Scenario 0 | R26: Scenario 1 | AG26: Scenario 2 | AV26: Scenario 3 | BJ26: Fine
B27: 0 | C27: 1 | D27: 2 | E27: 3 | F27: 4 | G27: 5 | H27: 6 | I27: 7 | J27: 8 | K27: 9 | L27: 10 | M27: 11 | N27: 12 | O27: 13 | P27: 14 | Q27: 15 | R27: 16 | S27: 17 | T27: 18 | U27: 19 | V27: 20 | W27: 21 | X27: 22 | Y27: 23 | Z27: 24 | AA27: 25 | AB27: 26 | AC27: 27 | AD27: 28 | AE27: 29 | AF27: 30 | AG27: 31 | AH27: 32 | AI27: 33 | AJ27: 34 | AK27: 35 | AL27: 36 | AM27: 37 | AN27: 38 | AO27: 39 | AP27: 40 | AQ27: 41 | AR27: 42 | AS27: 43 | AT27: 44 | AU27: 45 | AV27: 46 | AW27: 47 | AX27: 48 | AY27: 49 | AZ27: 50 | BA27: 51 | BB27: 52 | BC27: 53 | BD27: 54 | BE27: 55 | BF27: 56 | BG27: 57 | BH27: 58 | BI27: 59 | BJ27: 60
A28: CF Statement | B28: 2025 | C28: 2026 | D28: 2027 | E28: 2028 | F28: 2029 | G28: 2030 | H28: 2031 | I28: 2032 | J28: 2033 | K28: 2034 | L28: 2035 | M28: 2036 | N28: 2037 | O28: 2038 | P28: 2039 | Q28: 2040 | R28: 2041 | S28: 2042 | T28: 2043 | U28: 2044 | V28: 2045 | W28: 2046 | X28: 2047 | Y28: 2048 | Z28: 2049 | AA28: 2050 | AB28: 2051 | AC28: 2052 | AD28: 2053 | AE28: 2054 | AF28: 2055 | AG28: 2056 | AH28: 2057 | AI28: 2058 | AJ28: 2059 | AK28: 2060 | AL28: 2061 | AM28: 2062 | AN28: 2063 | AO28: 2064 | AP28: 2065 | AQ28: 2066 | AR28: 2067 | AS28: 2068 | AT28: 2069 | AU28: 2070 | AV28: 2071 | AW28: 2072 | AX28: 2073 | AY28: 2074 | AZ28: 2075 | BA28: 2076 | BB28: 2077 | BC28: 2078 | BD28: 2079 | BE28: 2080 | BF28: 2081 | BG28: 2082 | BH28: 2083 | BI28: 2084 | BJ28: 2085
A29: EBITDA | C29: =C17 -> 2.5716987e+08 | D29: =D17 -> 2.6162816e+08 | E29: =E17 -> 2.6604855e+08 | F29: =F17 -> 2.7043242e+08 | G29: =G17 -> 2.7478107e+08 | H29: =H17 -> 2.7909577e+08 | I29: =I17 -> 2.8337773e+08 | J29: =J17 -> 2.8762817e+08 | ... BJ29: =BJ17 -> 4.5988682e+08
A30: Investment | B30: =-B23 -> -2141700000
A31: Taxes | C31: =C20 -> -61791490 | D31: =D20 -> -63035353 | E31: =E20 -> -64268640 | F31: =F20 -> -65491740 | G31: =G20 -> -66705015 | H31: =H20 -> -67908813 | I31: =I20 -> -69103481 | J31: =J20 -> -70289354 | ... BJ31: =BJ20 -> -1.1834952e+08
A32: Cash Flow | B32: =SUM(B29:B31) -> -2141700000 | C32: =SUM(C29:C31) -> 1.9537838e+08 | D32: =SUM(D29:D31) -> 1.9859281e+08 | E32: =SUM(E29:E31) -> 2.0177991e+08 | F32: =SUM(F29:F31) -> 2.0494068e+08 | G32: =SUM(G29:G31) -> 2.0807606e+08 | H32: =SUM(H29:H31) -> 2.1118695e+08 | I32: =SUM(I29:I31) -> 2.1427425e+08 | ... BJ32: =SUM(BJ29:BJ31) -> 3.415373e+08
A33: Cumulative Cash flow | B33: =B32 -> -2141700000 | C33: =C32+B33 -> -1.9463216e+09 | D33: =D32+C33 -> -1.7477288e+09 | E33: =E32+D33 -> -1.5459489e+09 | F33: =F32+E33 -> -1.3410082e+09 | G33: =G32+F33 -> -1.1329322e+09 | H33: =H32+G33 -> -9.2174521e+08 | I33: =I32+H33 -> -7.0747096e+08 | J33: =J32+I33 -> -4.9013215e+08 | ... P33: =P32+O33 -> 8.7708899e+08 | Q33: =Q32 -> 2.3822374e+08 | R33: =R32+Q33 -> 4.8081239e+08 | S33: =S32+R33 -> 7.2553156e+08 | T33: =T32+S33 -> 9.7239031e+08 | U33: =U32+T33 -> 1.2213978e+09 | V33: =V32+U33 -> 1.4725632e+09 | W33: =W32+V33 -> 1.7258958e+09 | X33: =X32+W33 -> 1.9814051e+09 | Y33: =Y32+X33 -> 2.2391005e+09 | ... BJ33: =BJ32+BI33 -> 1.3361683e+10
A35: Discounted CF | C35: =C32/(1+$V$2)^C27 -> 1.8607465e+08 | D35: =D32/(1+$V$2)^D27 -> 1.8012953e+08 | E35: =E32/(1+$V$2)^E27 -> 1.7430507e+08 | F35: =F32/(1+$V$2)^F27 -> 1.6860521e+08 | G35: =G32/(1+$V$2)^G27 -> 1.6303304e+08 | H35: =H32/(1+$V$2)^H27 -> 1.5759095e+08 | I35: =I32/(1+$V$2)^I27 -> 1.5228071e+08 | J35: =J32/(1+$V$2)^J27 -> 1.4710346e+08 | ... BJ35: =BJ32/(1+$V$2)^BJ27 -> 18284378
A36: S DCF | B36: =SUM(C35:BJ35) -> 4.5719942e+09
A37: Initial Investment | B37: =B30 -> -2141700000
A38: NPV | B38: =B36+B37 -> 2.4302942e+09
A39: IRR | B39: =IRR(B32:BJ32) -> 0.10391419

Sheet Middle of the Road
B1: Scenario 0 | C1: Scenario 1 | D1: Scenario 2 | E1: Scenario 3 | H1: Scenario 0 | I1: Scenario 1 | J1: Scenario 2 | K1: Scenario 3 | N1: Initial CAPEX | T1: Tax rate (ires + irap) | V1: Discount Rate
A2: Energy to Community (MWh) | B2: =SUM('Output Produzione'!C3:C14) -> 369257.26 | C2: =SUM('Output Produzione'!C17:C28) -> 334190.92 | D2: =SUM('Output Produzione'!C31:C42) -> 292224.77 | E2: =SUM('Output Produzione'!C45:C56) -> 272576.69 | G2: Community price (€/MWh) | H2: ='Prezzi Energia Vari'!B31 -> 104.72089 | I2: ='Prezzi Energia Vari'!D31 -> 105.44537 | J2: ='Prezzi Energia Vari'!F31 -> 106.06665 | K2: ='Prezzi Energia Vari'!H31 -> 106.29154 | N2: ='OPEX and CAPEX'!C4 -> 2141700000 | T2: 0.279 | V2: 0.05
A3: Energy to Market (MWh) | B3: =354*0.98*8760-B2 -> 2669761.9 | C3: =SUM('Output Produzione'!D17:D28) -> 477231.38 | D3: =SUM('Output Produzione'!D31:D42) -> 519155.54 | E3: =SUM('Output Produzione'!D45:D56) -> 579243.71 | G3: Market price (€/MWh) | H3: ='Prezzi Energia Vari'!B34 -> 116.35655 | I3: ='Prezzi Energia Vari'!D34 -> 117.16153 | J3: ='Prezzi Energia Vari'!F34 -> 117.85183 | K3: ='Prezzi Energia Vari'!H34 -> 118.10171
C4: =354*0.98*8760-C2 -> 2704828.3
B6: Scenario 0 | R6: Scenario 1 | AG6: Scenario 2 | AV6: Scenario 3 | BJ6: Fine
B7: 0 | C7: 1 | D7: 2 | E7: 3 | F7: 4 | G7: 5 | H7: 6 | I7: 7 | J7: 8 | K7: 9 | L7: 10 | M7: 11 | N7: 12 | O7: 13 | P7: 14 | Q7: 15 | R7: 16 | S7: 17 | T7: 18 | U7: 19 | V7: 20 | W7: 21 | X7: 22 | Y7: 23 | Z7: 24 | AA7: 25 | AB7: 26 | AC7: 27 | AD7: 28 | AE7: 29 | AF7: 30 | AG7: 31 | AH7: 32 | AI7: 33 | AJ7: 34 | AK7: 35 | AL7: 36 | AM7: 37 | AN7: 38 | AO7: 39 | AP7: 40 | AQ7: 41 | AR7: 42 | AS7: 43 | AT7: 44 | AU7: 45 | AV7: 46 | AW7: 47 | AX7: 48 | AY7: 49 | AZ7: 50 | BA7: 51 | BB7: 52 | BC7: 53 | BD7: 54 | BE7: 55 | BF7: 56 | BG7: 57 | BH7: 58 | BI7: 59 | BJ7: 60
A8: Income Statement | B8: 2025 | C8: 2026 | D8: 2027 | E8: 2028 | F8: 2029 | G8: 2030 | H8: 2031 | I8: 2032 | J8: 2033 | K8: 2034 | L8: 2035 | M8: 2036 | N8: 2037 | O8: 2038 | P8: 2039 | Q8: 2040 | R8: 2041 | S8: 2042 | T8: 2043 | U8: 2044 | V8: 2045 | W8: 2046 | X8: 2047 | Y8: 2048 | Z8: 2049 | AA8: 2050 | AB8: 2051 | AC8: 2052 | AD8: 2053 | AE8: 2054 | AF8: 2055 | AG8: 2056 | AH8: 2057 | AI8: 2058 | AJ8: 2059 | AK8: 2060 | AL8: 2061 | AM8: 2062 | AN8: 2063 | AO8: 2064 | AP8: 2065 | AQ8: 2066 | AR8: 2067 | AS8: 2068 | AT8: 2069 | AU8: 2070 | AV8: 2071 | AW8: 2072 | AX8: 2073 | AY8: 2074 | AZ8: 2075 | BA8: 2076 | BB8: 2077 | BC8: 2078 | BD8: 2079 | BE8: 2080 | BF8: 2081 | BG8: 2082 | BH8: 2083 | BI8: 2084 | BJ8: 2085
A9: Electricity | C9: =($B$2*'Prezzi Energia Vari'!$B$31+$B$3*'Prezzi Energia Vari'!$B$34)*1.0063742415 -> 3.5153983e+08 | D9: =C9*1.0063742415 -> 3.5378063e+08 | E9: =D9*1.006374 -> 3.5603563e+08 | F9: =E9*1.006374 -> 3.58305e+08 | G9: =F9*1.006374 -> 3.6058884e+08 | H9: =G9*1.006374 -> 3.6288723e+08 | I9: =H9*1.006374 -> 3.6520027e+08 | J9: =I9*1.006374 -> 3.6752806e+08 | K9: =J9*1.006374 -> 3.6987068e+08 | L9: =K9*1.006374 -> 3.7222824e+08 | ... Q9: =P9*1.006374 -> 3.8424335e+08 | R9: =(C2*'Prezzi Energia Vari'!D31+C4*'Prezzi Energia Vari'!D34)*1.1*1.006374 -> 3.8982377e+08 | S9: =R9*1.006374 -> 3.9230851e+08 | T9: =S9*1.006374 -> 3.9480908e+08 | U9: =T9*1.006374 -> 3.9732559e+08 | V9: =U9*1.006374 -> 3.9985815e+08 | W9: ='Base Case'!W8 -> 1.041635e+08 | X9: =W9*1.006374 -> 1.0482743e+08 | Y9: =X9*1.006374 -> 1.054956e+08 | Z9: =Y9*1.006374 -> 1.0616803e+08 | AA9: =Z9*1.006374 -> 1.0684475e+08 | AB9: =AA9*1.006374 -> 1.0752578e+08 | AC9: =AB9*1.006374 -> 1.0821115e+08 | AD9: =AC9*1.006374 -> 1.0890088e+08 | AE9: =AD9*1.006374 -> 1.0959502e+08 | AF9: =AE9*1.006374 -> 1.1029358e+08 | AG9: =(D2*'Prezzi Energia Vari'!F31+D3*'Prezzi Energia Vari'!F34)*1.1^2*1.006374 -> 1.122472e+08 | AH9: =AG9*1.006374 -> 1.1296266e+08 | AI9: =AH9*1.006374 -> 1.1368269e+08 | AJ9: =AI9*1.006374 -> 1.144073e+08 | AK9: =AJ9*1.006374 -> 1.1513653e+08 | AL9: =AK9*1.006374 -> 1.1587041e+08 | AM9: =AL9*1.006374 -> 1.1660897e+08 | AN9: =AM9*1.006374 -> 1.1735224e+08 | AO9: =AN9*1.006374 -> 1.1810024e+08 | ... AU9: =AT9*1.006374 -> 1.2268945e+08 | AV9: =(E2*'Prezzi Energia Vari'!H31+E3*'Prezzi Energia Vari'!H34)*1.1^3*1.006374 -> 1.3044197e+08 | AW9: =AV9*1.006374 -> 1.3127341e+08 | AX9: =AW9*1.006374 -> 1.3211015e+08 | AY9: =AX9*1.006374 -> 1.3295222e+08 | AZ9: =AY9*1.006374 -> 1.3379965e+08 | BA9: =AZ9*1.006374 -> 1.3465249e+08 | BB9: =BA9*1.006374 -> 1.3551077e+08 | BC9: =BB9*1.006374 -> 1.3637451e+08 | BD9: =BC9*1.006374 -> 1.3724376e+08 | ... BJ9: =BI9*1.006374 -> 1.4257687e+08
A10: Hydrogen | W10: ='Base Case'!W9 -> 35005696 | X10: =W10 -> 35005696 | Y10: =X10 -> 35005696 | Z10: =Y10 -> 35005696 | AA10: =Z10 -> 35005696 | AB10: =AA10 -> 35005696 | AC10: =AB10 -> 35005696 | AD10: =AC10 -> 35005696 | AE10: =AD10 -> 35005696 | AF10: =AE10 -> 35005696 | AG10: ='Output Produzione'!$F$31*'Prezzi Energia Vari'!$B$24*0.7*1.006374 -> 35892150 | AH10: =AG10*1.006374 -> 36120927 | AI10: =AH10*1.006374 -> 36351161 | AJ10: =AI10*1.006374 -> 36582864 | AK10: =AJ10*1.006374 -> 36816043 | AL10: =AK10*1.006374 -> 37050708 | AM10: =AL10*1.006374 -> 37286870 | AN10: =AM10*1.006374 -> 37524536 | AO10: =AN10*1.006374 -> 37763717 | ... AT10: =AS10*1.006374 -> 38982688 | AU10: ='Output Produzione'!$F$45*'Prezzi Energia Vari'!$B$24*0.7*1.1*1.006374 -> 38881794 | AV10: =AU10*1.006374 -> 39129626 | AW10: =AV10*1.006374 -> 39379038 | AX10: =AW10*1.006374 -> 39630040 | AY10: =AX10*1.006374 -> 39882642 | AZ10: =AY10*1.006374 -> 40136854 | BA10: =AZ10*1.006374 -> 40392687 | BB10: =BA10*1.006374 -> 40650150 | BC10: =BB10*1.006374 -> 40909254 | ... BJ10: =BI10*1.006374 -> 42769819
A11: Syngas | W11: ='Base Case'!W10 -> 29088240 | X11: =W11 -> 29088240 | Y11: =X11 -> 29088240 | Z11: =Y11 -> 29088240 | AA11: =Z11 -> 29088240 | AB11: =AA11 -> 29088240 | AC11: =AB11 -> 29088240 | AD11: =AC11 -> 29088240 | AE11: =AD11 -> 29088240 | AF11: =AE11 -> 29088240 | AG11: ='Output Produzione'!$G$31*'Prezzi Energia Vari'!$B$27*0.65*1.006374 -> 27354716 | AH11: =AG11*1.006374 -> 27529075 | AI11: =AH11*1.006374 -> 27704546 | AJ11: =AI11*1.006374 -> 27881135 | AK11: =AJ11*1.006374 -> 28058849 | AL11: =AK11*1.006374 -> 28237696 | AM11: =AL11*1.006374 -> 28417683 | AN11: =AM11*1.006374 -> 28598817 | AO11: =AN11*1.006374 -> 28781106 | ... AT11: =AS11*1.006374 -> 29710128 | AU11: ='Output Produzione'!$G$45*'Prezzi Energia Vari'!$B$27*0.65*1.1*1.006374 -> 30049486 | AV11: =AU11*1.006374 -> 30241021 | AW11: =AV11*1.006374 -> 30433778 | AX11: =AW11*1.006374 -> 30627763 | AY11: =AX11*1.006374 -> 30822984 | AZ11: =AY11*1.006374 -> 31019450 | BA11: =AZ11*1.006374 -> 31217168 | BB11: =BA11*1.006374 -> 31416146 | BC11: =BB11*1.006374 -> 31616392 | ... BJ11: =BI11*1.006374 -> 33054316
A12: Total operating revenues | C12: =C9+C10+C11 -> 3.5153983e+08 | D12: =D9+D10+D11 -> 3.5378063e+08 | E12: =E9+E10+E11 -> 3.5603563e+08 | F12: =F9+F10+F11 -> 3.58305e+08 | G12: =G9+G10+G11 -> 3.6058884e+08 | H12: =H9+H10+H11 -> 3.6288723e+08 | I12: =I9+I10+I11 -> 3.6520027e+08 | J12: =J9+J10+J11 -> 3.6752806e+08 | ... BJ12: =BJ9+BJ10+BJ11 -> 2.18401e+08
A13: SMR | C13: =-('OPEX and CAPEX'!$E$4)*0.97650215 -> -94369959 | D13: =C13*0.97650215 -> -92152468 | E13: =D13*0.97650215 -> -89987083 | F13: =E13*0.97650215 -> -87872580 | G13: =F13*0.97650215 -> -85807764 | H13: =G13*0.97650215 -> -83791466 | I13: =H13*0.97650215 -> -81822546 | J13: =I13*0.97650215 -> -79899892 | K13: =J13*0.97650215 -> -78022417 | ... Q13: =P13*0.97650215 -> -67648570 | R13: =-('OPEX and CAPEX'!$E$4)*0.7*0.993 -> -67175027 | S13: =R13*0.993 -> -66704802 | T13: =S13*0.993 -> -66237869 | U13: =T13*0.993 -> -65774204 | V13: =U13*0.993 -> -65313784 | W13: =V13*0.993 -> -64856588 | X13: =W13*0.993 -> -64402592 | Y13: =X13*0.993 -> -63951773 | Z13: =Y13*0.993 -> -63504111 | ... AF13: =AE13*0.993 -> -60883180 | AG13: =AF13 -> -60883180 | AH13: =AG13 -> -60883180 | AI13: =AH13 -> -60883180 | AJ13: =AI13 -> -60883180 | AK13: =AJ13 -> -60883180 | AL13: =AK13 -> -60883180 | AM13: =AL13 -> -60883180 | AN13: =AM13 -> -60883180 | ... BJ13: =BI13 -> -60883180
A14: Hydrogen System | W14: ='Base Case'!V13 -> -4658231.4 | X14: =W14*0.993 -> -4625623.8 | Y14: =X14*0.993 -> -4593244.4 | Z14: =Y14*0.993 -> -4561091.7 | AA14: =Z14*0.993 -> -4529164 | AB14: =AA14*0.993 -> -4497459.9 | AC14: =AB14*0.993 -> -4465977.7 | AD14: =AC14*0.993 -> -4434715.8 | AE14: =AD14*0.993 -> -4403672.8 | AF14: =AE14*0.993 -> -4372847.1 | AG14: =AF14 -> -4372847.1 | AH14: =AG14 -> -4372847.1 | AI14: =AH14 -> -4372847.1 | AJ14: =AI14 -> -4372847.1 | AK14: =AJ14 -> -4372847.1 | AL14: =AK14 -> -4372847.1 | AM14: =AL14 -> -4372847.1 | AN14: =AM14 -> -4372847.1 | ... BJ14: =BI14 -> -4372847.1
A15: Methanator | W15: ='Base Case'!V14 -> 0 | X15: =W15*'OPEX and CAPEX'!$O$20 -> 0 | Y15: =X15*'OPEX and CAPEX'!$O$20 -> 0 | Z15: =Y15*'OPEX and CAPEX'!$O$20 -> 0 | AA15: =Z15*'OPEX and CAPEX'!$O$20 -> 0 | AB15: =AA15*'OPEX and CAPEX'!$O$20 -> 0 | AC15: =AB15*'OPEX and CAPEX'!$O$20 -> 0 | AD15: =AC15*'OPEX and CAPEX'!$O$20 -> 0 | AE15: =AD15*'OPEX and CAPEX'!$O$20 -> 0 | AF15: =AE15*'OPEX and CAPEX'!$O$20 -> 0 | AG15: =-('OPEX and CAPEX'!$Q$4)*0.65*0.6933*'OPEX and CAPEX'!$P$20 -> 0 | AH15: =AG15*'OPEX and CAPEX'!$P$20 -> 0 | AI15: =AH15*'OPEX and CAPEX'!$P$20 -> 0 | AJ15: =AI15*'OPEX and CAPEX'!$P$20 -> 0 | AK15: =AJ15*'OPEX and CAPEX'!$P$20 -> 0 | AL15: =AK15*'OPEX and CAPEX'!$P$20 -> 0 | AM15: =AL15*'OPEX and CAPEX'!$P$20 -> 0 | AN15: =AM15*'OPEX and CAPEX'!$P$20 -> 0 | AO15: =AN15*'OPEX and CAPEX'!$P$20 -> 0 | ... AU15: =AT15*'OPEX and CAPEX'!$P$20 -> 0 | AV15: =-('OPEX and CAPEX'!$R$4)*0.65*0.6933*0.7222*'OPEX and CAPEX'!$Q$20 -> 0 | AW15: =-('OPEX and CAPEX'!$R$4)*0.65*0.6933*0.7222*'OPEX and CAPEX'!$Q$20 -> 0 | AX15: =-('OPEX and CAPEX'!$R$4)*0.65*0.6933*0.7222*'OPEX and CAPEX'!$Q$20 -> 0 | AY15: =-('OPEX and CAPEX'!$R$4)*0.65*0.6933*0.7222*'OPEX and CAPEX'!$Q$20 -> 0 | AZ15: =-('OPEX and CAPEX'!$R$4)*0.65*0.6933*0.7222*'OPEX and CAPEX'!$Q$20 -> 0 | BA15: =-('OPEX and CAPEX'!$R$4)*0.65*0.6933*0.7222*'OPEX and CAPEX'!$Q$20 -> 0 | BB15: =-('OPEX and CAPEX'!$R$4)*0.65*0.6933*0.7222*'OPEX and CAPEX'!$Q$20 -> 0 | BC15: =-('OPEX and CAPEX'!$R$4)*0.65*0.6933*0.7222*'OPEX and CAPEX'!$Q$20 -> 0 | ... BJ15: =-('OPEX and CAPEX'!$R$4)*0.65*0.6933*0.7222*'OPEX and CAPEX'!$Q$20 -> 0
A16: Turbine | W16: ='Base Case'!V15 -> -327355 | X16: =-'OPEX and CAPEX'!$E$22 -> -327355 | Y16: =-'OPEX and CAPEX'!$E$22 -> -327355 | Z16: =-'OPEX and CAPEX'!$E$22 -> -327355 | AA16: =-'OPEX and CAPEX'!$E$22 -> -327355 | AB16: =-'OPEX and CAPEX'!$E$22 -> -327355 | AC16: =-'OPEX and CAPEX'!$E$22 -> -327355 | AD16: =-'OPEX and CAPEX'!$E$22 -> -327355 | AE16: =-'OPEX and CAPEX'!$E$22 -> -327355 | ... BJ16: =-'OPEX and CAPEX'!$E$22 -> -327355
A17: OpEx | C17: =C13+C14+C15+C16 -> -94369959 | D17: =D13+D14+D15+D16 -> -92152468 | E17: =E13+E14+E15+E16 -> -89987083 | F17: =F13+F14+F15+F16 -> -87872580 | G17: =G13+G14+G15+G16 -> -85807764 | H17: =H13+H14+H15+H16 -> -83791466 | I17: =I13+I14+I15+I16 -> -81822546 | J17: =J13+J14+J15+J16 -> -79899892 | ... BJ17: =BJ13+BJ14+BJ15+BJ16 -> -65583383
A18: Investment | B18: ='OPEX and CAPEX'!C4 -> 2141700000 | W18: =('OPEX and CAPEX'!C7+'OPEX and CAPEX'!C10+'OPEX and CAPEX'!C13+'OPEX and CAPEX'!L4)*0.7+'OPEX and CAPEX'!C22 -> 236273000 | AQ18: =W18*0.85+'OPEX and CAPEX'!C22 -> 224032050
A19: EBITDA | C19: =C12+C17 -> 2.5716987e+08 | D19: =D12+D17 -> 2.6162816e+08 | E19: =E12+E17 -> 2.6604855e+08 | F19: =F12+F17 -> 2.7043242e+08 | G19: =G12+G17 -> 2.7478107e+08 | H19: =H12+H17 -> 2.7909577e+08 | I19: =I12+I17 -> 2.8337773e+08 | J19: =J12+J17 -> 2.8762817e+08 | ... BJ19: =BJ12+BJ17 -> 1.5281762e+08
A20: Depreciation | C20: =-('OPEX and CAPEX'!C4/'OPEX and CAPEX'!F4+'OPEX and CAPEX'!C7/'OPEX and CAPEX'!F7+'OPEX and CAPEX'!C10/'OPEX and CAPEX'!F10+'OPEX and CAPEX'!C13/'OPEX and CAPEX'!F13+'OPEX and CAPEX'!L4/'OPEX and CAPEX'!S4) -> -50989500 | D20: =$C$20 -> -50989500 | E20: =$C$20 -> -50989500 | F20: =$C$20 -> -50989500 | G20: =$C$20 -> -50989500 | H20: =$C$20 -> -50989500 | I20: =$C$20 -> -50989500 | J20: =$C$20 -> -50989500 | K20: =$C$20 -> -50989500 | ... BJ20: =$C$20 -> -50989500
A21: EBIT | C21: =C19+C20 -> 2.0618037e+08 | D21: =D19+D20 -> 2.1063866e+08 | E21: =E19+E20 -> 2.1505905e+08 | F21: =F19+F20 -> 2.1944292e+08 | G21: =G19+G20 -> 2.2379157e+08 | H21: =H19+H20 -> 2.2810627e+08 | I21: =I19+I20 -> 2.3238823e+08 | J21: =J19+J20 -> 2.3663867e+08 | ... BJ21: =BJ19+BJ20 -> 1.0182812e+08
A22: Taxes | C22: =-$T$2*C21 -> -57524324 | D22: =-$T$2*D21 -> -58768187 | E22: =-$T$2*E21 -> -60001474 | F22: =-$T$2*F21 -> -61224575 | G22: =-$T$2*G21 -> -62437849 | H22: =-$T$2*H21 -> -63641648 | I22: =-$T$2*I21 -> -64836315 | J22: =-$T$2*J21 -> -66022188 | ... BJ22: =-$T$2*BJ21 -> -28410046
A23: Net Income | C23: =C21+C22 -> 1.4865605e+08 | D23: =D21+D22 -> 1.5187048e+08 | E23: =E21+E22 -> 1.5505757e+08 | F23: =F21+F22 -> 1.5821835e+08 | G23: =G21+G22 -> 1.6135372e+08 | H23: =H21+H22 -> 1.6446462e+08 | I23: =I21+I22 -> 1.6755191e+08 | J23: =J21+J22 -> 1.7061648e+08 | ... BJ23: =BJ21+BJ22 -> 73418075
A25: Present value of costs | B25: =B18 -> 2141700000 | C25: =(ABS(C17)+C18)/(1+$V$2)^C7 -> 89876152 | D25: =(ABS(D17)+D18)/(1+$V$2)^D7 -> 83585005 | E25: =(ABS(E17)+E18)/(1+$V$2)^E7 -> 77734226 | F25: =(ABS(F17)+F18)/(1+$V$2)^F7 -> 72292989 | G25: =(ABS(G17)+G18)/(1+$V$2)^G7 -> 67232628 | H25: =(ABS(H17)+H18)/(1+$V$2)^H7 -> 62526482 | I25: =(ABS(I17)+I18)/(1+$V$2)^I7 -> 58149756 | J25: =(ABS(J17)+J18)/(1+$V$2)^J7 -> 54079392 | ... BJ25: =(ABS(BJ17)+BJ18)/(1+$V$2)^BJ7 -> 3511040.7 | BK25: =SUM(B25:BJ25) -> 3.6773355e+09
A26: Present value of energy | C26: =($B$3+$B$2)*1000/((1+$V$2)^C7) -> 2894304000 | D26: =($B$3+$B$2)*1000/((1+$V$2)^D7) -> 2756480000 | E26: =($B$3+$B$2)*1000/((1+$V$2)^E7) -> 2.625219e+09 | F26: =($B$3+$B$2)*1000/((1+$V$2)^F7) -> 2.5002086e+09 | G26: =($B$3+$B$2)*1000/((1+$V$2)^G7) -> 2.3811511e+09 | H26: =($B$3+$B$2)*1000/((1+$V$2)^H7) -> 2.2677629e+09 | I26: =($B$3+$B$2)*1000/((1+$V$2)^I7) -> 2.1597742e+09 | J26: =($B$3+$B$2)*1000/((1+$V$2)^J7) -> 2.0569278e+09 | ... V26: =($B$3+$B$2)*1000/((1+$V$2)^V7) -> 1.1453744e+09 | W26: =(($C$3+$C$2+'Output Produzione'!$F$17+'Output Produzione'!$G$17)/(1+$V$2)^W7)*1000 -> 5.0409281e+08 | X26: =(($C$3+$C$2+'Output Produzione'!$F$17+'Output Produzione'!$G$17)/(1+$V$2)^X7)*1000 -> 4.8008839e+08 | Y26: =(($C$3+$C$2+'Output Produzione'!$F$17+'Output Produzione'!$G$17)/(1+$V$2)^Y7)*1000 -> 4.5722704e+08 | Z26: =(($C$3+$C$2+'Output Produzione'!$F$17+'Output Produzione'!$G$17)/(1+$V$2)^Z7)*1000 -> 4.3545432e+08 | AA26: =(($C$3+$C$2+'Output Produzione'!$F$17+'Output Produzione'!$G$17)/(1+$V$2)^AA7)*1000 -> 4.147184e+08 | AB26: =(($C$3+$C$2+'Output Produzione'!$F$17+'Output Produzione'!$G$17)/(1+$V$2)^AB7)*1000 -> 3.949699e+08 | AC26: =(($C$3+$C$2+'Output Produzione'!$F$17+'Output Produzione'!$G$17)/(1+$V$2)^AC7)*1000 -> 3.7616181e+08 | AD26: =(($C$3+$C$2+'Output Produzione'!$F$17+'Output Produzione'!$G$17)/(1+$V$2)^AD7)*1000 -> 3.5824935e+08 | ... AF26: =(($C$3+$C$2+'Output Produzione'!$F$17+'Output Produzione'!$G$17)/(1+$V$2)^AF7)*1000 -> 3.2494272e+08 | AG26: =(($D$3+$D$2+'Output Produzione'!$F$31+'Output Produzione'!$G$31)/(1+$V$2)^AG7)*1000 -> 3.107513e+08 | AH26: =(($D$3+$D$2+'Output Produzione'!$F$31+'Output Produzione'!$G$31)/(1+$V$2)^AH7)*1000 -> 2.9595362e+08 | AI26: =(($D$3+$D$2+'Output Produzione'!$F$31+'Output Produzione'!$G$31)/(1+$V$2)^AI7)*1000 -> 2.8186059e+08 | AJ26: =(($D$3+$D$2+'Output Produzione'!$F$31+'Output Produzione'!$G$31)/(1+$V$2)^AJ7)*1000 -> 2.6843866e+08 | AK26: =(($D$3+$D$2+'Output Produzione'!$F$31+'Output Produzione'!$G$31)/(1+$V$2)^AK7)*1000 -> 2.5565586e+08 | AL26: =(($D$3+$D$2+'Output Produzione'!$F$31+'Output Produzione'!$G$31)/(1+$V$2)^AL7)*1000 -> 2.4348178e+08 | AM26: =(($D$3+$D$2+'Output Produzione'!$F$31+'Output Produzione'!$G$31)/(1+$V$2)^AM7)*1000 -> 2.3188741e+08 | AN26: =(($D$3+$D$2+'Output Produzione'!$F$31+'Output Produzione'!$G$31)/(1+$V$2)^AN7)*1000 -> 2.2084515e+08 | ... AU26: =(($D$3+$D$2+'Output Produzione'!$F$31+'Output Produzione'!$G$31)/(1+$V$2)^AU7)*1000 -> 1.5695052e+08 | AV26: =(($E$3+$E$2+'Output Produzione'!$F$45+'Output Produzione'!$G$45)/(1+$V$2)^AV7)*1000 -> 1.5305478e+08 | AW26: =(($E$3+$E$2+'Output Produzione'!$F$45+'Output Produzione'!$G$45)/(1+$V$2)^AW7)*1000 -> 1.4576646e+08 | AX26: =(($E$3+$E$2+'Output Produzione'!$F$45+'Output Produzione'!$G$45)/(1+$V$2)^AX7)*1000 -> 1.388252e+08 | AY26: =(($E$3+$E$2+'Output Produzione'!$F$45+'Output Produzione'!$G$45)/(1+$V$2)^AY7)*1000 -> 1.3221447e+08 | AZ26: =(($E$3+$E$2+'Output Produzione'!$F$45+'Output Produzione'!$G$45)/(1+$V$2)^AZ7)*1000 -> 1.2591855e+08 | BA26: =(($E$3+$E$2+'Output Produzione'!$F$45+'Output Produzione'!$G$45)/(1+$V$2)^BA7)*1000 -> 1.1992242e+08 | BB26: =(($E$3+$E$2+'Output Produzione'!$F$45+'Output Produzione'!$G$45)/(1+$V$2)^BB7)*1000 -> 1.1421183e+08 | BC26: =(($E$3+$E$2+'Output Produzione'!$F$45+'Output Produzione'!$G$45)/(1+$V$2)^BC7)*1000 -> 1.0877317e+08 | ... BJ26: =(($E$3+$E$2+'Output Produzione'!$F$45+'Output Produzione'!$G$45)/(1+$V$2)^BJ7)*1000 -> 77303064 | BK26: =SUM(C26:BJ26) -> 4.7014847e+10
A27: LCOE (€/kWh) | B27: =BK25/BK26 -> 0.078216473
